<?xml version="1.0" ?>
<!-- =================================================================================== -->
<!-- |    This document was autogenerated by xacro from innok_heros.xacro              | -->
<!-- |    EDITING THIS FILE BY HAND IS NOT RECOMMENDED                                 | -->
<!-- =================================================================================== -->
<robot name="innok_heros_full">
  <!-- swing_axle | caster | 4wd -->
  <material name="Grey">
    <color rgba="0.66 0.66 0.66 1"/>
  </material>
  <!-- IMU -->
  <gazebo>
    <plugin filename="libgazebo_ros_imu.so" name="imu_plugin">
      <alwaysOn>true</alwaysOn>
      <bodyName>base_link</bodyName>
      <topicName>imu</topicName>
      <serviceName>imu_service</serviceName>
      <gaussianNoise>0.0</gaussianNoise>
      <updateRate>20.0</updateRate>
    </plugin>
  </gazebo>
  <!-- Camera -->
  <joint name="camera_joint" type="fixed">
    <axis xyz="0 1 0"/>
    <origin rpy="0 0 0" xyz="0.8 0.1 0.07"/>
    <parent link="base_link"/>
    <child link="camera_link"/>
  </joint>
  <link name="camera_link">
    <collision>
      <origin rpy="0 0 0" xyz="0 0 0"/>
      <geometry>
        <box size="0.05 0.05 0.05"/>
      </geometry>
    </collision>
    <visual>
      <origin rpy="0 0 0" xyz="0 0 0"/>
      <geometry>
        <box size="0.05 0.05 0.05"/>
      </geometry>
      <material name="blue">
        <color rgba="0.0 0.0 0.8 1.0"/>
      </material>
    </visual>
    <inertial>
      <mass value="1e-5"/>
      <origin rpy="0 0 0" xyz="0 0 0"/>
      <inertia ixx="1e-6" ixy="0" ixz="0" iyy="1e-6" iyz="0" izz="1e-6"/>
    </inertial>
  </link>
  <gazebo reference="camera_link">
    <sensor name="camera1" type="camera">
      <update_rate>30.0</update_rate>
      <camera name="head">
        <horizontal_fov>1.3962634</horizontal_fov>
        <image>
          <width>800</width>
          <height>800</height>
          <format>R8G8B8</format>
        </image>
        <clip>
          <near>0.02</near>
          <far>300</far>
        </clip>
        <noise>
          <type>gaussian</type>
          <mean>0.0</mean>
          <stddev>0.007</stddev>
        </noise>
      </camera>
      <plugin filename="libgazebo_ros_camera.so" name="camera_controller">
        <alwaysOn>true</alwaysOn>
        <updateRate>0.0</updateRate>
        <cameraName>heros/camera1</cameraName>
        <imageTopicName>image_raw</imageTopicName>
        <cameraInfoTopicName>camera_info</cameraInfoTopicName>
        <frameName>camera_link</frameName>
        <hackBaseline>0.07</hackBaseline>
        <distortionK1>0.0</distortionK1>
        <distortionK2>0.0</distortionK2>
        <distortionK3>0.0</distortionK3>
        <distortionT1>0.0</distortionT1>
        <distortionT2>0.0</distortionT2>
      </plugin>
    </sensor>
  </gazebo>
  <!-- GPS -->
  <gazebo>
    <plugin filename="libhector_gazebo_ros_gps.so" name="gps_controller">
      <alwayson>true</alwayson>
      <updaterate>1.0</updaterate>
      <bodyname>base_link</bodyname>
      <topicname>/fix</topicname>
      <velocitytopicname>/fix_velocity</velocitytopicname>
      <drift>5.0 5.0 5.0</drift>
      <gaussiannoise>0.1 0.1 0.1</gaussiannoise>
      <velocitydrift>0 0 0</velocitydrift>
      <velocitygaussiannoise>0.1 0.1 0.1</velocitygaussiannoise>
    </plugin>
  </gazebo>
  <link name="base_link"/>
  <link name="beam_link">
    <inertial>
      <origin rpy="0 0 0" xyz="0.40 0 0.02"/>
      <mass value="2"/>
      <inertia ixx="0.003" ixy="0" ixz="0" iyy="0.09" iyz="0" izz="0.09"/>
    </inertial>
    <visual>
      <origin rpy="0 0 0" xyz="0 0 0"/>
      <geometry>
        <mesh filename="package://professor_robot/meshes/beam.STL"/>
      </geometry>
      <material name="white">
        <color rgba="1 1 1 1"/>
      </material>
    </visual>
    <collision>
      <origin rpy="0 0 0" xyz="0.4 0 0.02"/>
      <geometry>
        <box size="0.8 0.160 0.040"/>
      </geometry>
    </collision>
  </link>
  <joint name="beam_joint" type="fixed">
    <origin rpy="0 0 0" xyz="0 0 0"/>
    <parent link="base_link"/>
    <child link="beam_link"/>
    <axis xyz="0 0 0"/>
  </joint>
  <link name="wheel_rear_left">
    <collision>
      <origin rpy="-1.5707963267948966 0 0" xyz="0 0.115 0"/>
      <geometry>
        <cylinder length="0.16" radius="0.16"/>
      </geometry>
    </collision>
    <visual>
      <origin rpy="0 0 0" xyz="0 0 0"/>
      <geometry>
        <mesh filename="package://professor_robot/meshes/wheel.STL"/>
      </geometry>
      <material name="">
        <color rgba="0.25 0.25 0.25 1"/>
      </material>
    </visual>
    <inertial>
      <origin rpy="0 0 0" xyz="0 0.115 0"/>
      <mass value="5.4"/>
      <inertia ixx="0.046" ixy="0" ixz="0" iyy="0.072" iyz="0" izz="0.045"/>
    </inertial>
  </link>
  <gazebo reference="wheel_rear_left">
    <gravity>true</gravity>
    <mu1>10</mu1>
    <mu2>10</mu2>
    <kd>1</kd>
    <kp>1000000000.0</kp>
    <fdir1>0 0 1</fdir1>
    <selfCollide>false</selfCollide>
    <material>Gazebo/Grey</material>
  </gazebo>
  <joint name="joint_base_wheel_rear_left" type="continuous">
    <parent link="drive_box_rear"/>
    <child link="wheel_rear_left"/>
    <origin rpy="0 0 0.0" xyz="0.063 0.162 -0.184"/>
    <axis xyz="0 1 0"/>
  </joint>
  <transmission name="trans_wheel_rear_left">
    <type>transmission_interface/SimpleTransmission</type>
    <joint name="joint_base_wheel_rear_left">
      <hardwareInterface>hardware_interface/VelocityJointInterface</hardwareInterface>
    </joint>
    <actuator name="motor_wheel_rear_left">
      <mechanicalReduction>100</mechanicalReduction>
    </actuator>
  </transmission>
  <link name="wheel_rear_right">
    <collision>
      <origin rpy="-1.5707963267948966 0 0" xyz="0 0.115 0"/>
      <geometry>
        <cylinder length="0.16" radius="0.16"/>
      </geometry>
    </collision>
    <visual>
      <origin rpy="0 0 0" xyz="0 0 0"/>
      <geometry>
        <mesh filename="package://professor_robot/meshes/wheel.STL"/>
      </geometry>
      <material name="">
        <color rgba="0.25 0.25 0.25 1"/>
      </material>
    </visual>
    <inertial>
      <origin rpy="0 0 0" xyz="0 0.115 0"/>
      <mass value="5.4"/>
      <inertia ixx="0.046" ixy="0" ixz="0" iyy="0.072" iyz="0" izz="0.045"/>
    </inertial>
  </link>
  <gazebo reference="wheel_rear_right">
    <gravity>true</gravity>
    <mu1>10</mu1>
    <mu2>10</mu2>
    <kd>1</kd>
    <kp>1000000000.0</kp>
    <fdir1>0 0 1</fdir1>
    <selfCollide>false</selfCollide>
    <material>Gazebo/Grey</material>
  </gazebo>
  <joint name="joint_base_wheel_rear_right" type="continuous">
    <parent link="drive_box_rear"/>
    <child link="wheel_rear_right"/>
    <origin rpy="0 0 3.141592653589793" xyz="0.063 -0.162 -0.184"/>
    <axis xyz="0 -1 0"/>
  </joint>
  <transmission name="trans_wheel_rear_right">
    <type>transmission_interface/SimpleTransmission</type>
    <joint name="joint_base_wheel_rear_right">
      <hardwareInterface>hardware_interface/VelocityJointInterface</hardwareInterface>
    </joint>
    <actuator name="motor_wheel_rear_right">
      <mechanicalReduction>100</mechanicalReduction>
    </actuator>
  </transmission>
  <link name="drive_box_rear">
    <inertial>
      <origin rpy="0 0 0" xyz="0.122 -0.0026 -0.136"/>
      <mass value="10.6"/>
      <inertia ixx="0.316" ixy="0" ixz="0" iyy="0.166" iyz="0" izz="0.307"/>
    </inertial>
    <visual>
      <origin rpy="0 0 0" xyz="0 0 0"/>
      <geometry>
        <mesh filename="package://professor_robot/meshes/drive_box.STL"/>
      </geometry>
      <material name="white">
        <color rgba="1 1 1 1"/>
      </material>
    </visual>
    <collision>
      <origin rpy="0 0 0" xyz="0.142 0 -0.124"/>
      <geometry>
        <box size="0.284 0.328 0.248"/>
      </geometry>
    </collision>
  </link>
  <joint name="drive_box_joint_rear" type="fixed">
    <origin rpy="0 0 0.0" xyz="0.018 0 -0.0065"/>
    <parent link="beam_link"/>
    <child link="drive_box_rear"/>
    <axis xyz="0 0 0"/>
  </joint>
  <link name="battery_box">
    <inertial>
      <origin rpy="0 0 0" xyz="0.064 0 -0.1"/>
      <mass value="4.71"/>
      <inertia ixx="0.114" ixy="0" ixz="0" iyy="0.05" iyz="0" izz="0.078"/>
    </inertial>
    <visual>
      <origin rpy="0 0 0" xyz="0 0 0"/>
      <geometry>
        <mesh filename="package://professor_robot/meshes/battery_box.STL"/>
      </geometry>
      <material name="white">
        <color rgba="1 1 1 1"/>
      </material>
    </visual>
    <collision>
      <origin rpy="0 0 0" xyz="0.062 0 -0.124"/>
      <geometry>
        <box size="0.124 0.328 0.248"/>
      </geometry>
    </collision>
  </link>
  <joint name="battery_box_joint" type="fixed">
    <origin rpy="0 0 0" xyz="0.336 0 -0.007"/>
    <parent link="beam_link"/>
    <child link="battery_box"/>
    <axis xyz="0 0 0"/>
  </joint>
  <link name="mounting_plate">
    <inertial>
      <origin rpy="0 0 0" xyz="0.319 0 -0.002"/>
      <mass value="4.35"/>
      <inertia ixx="0.133" ixy="0" ixz="0" iyy="0.278" iyz="0" izz="0.410"/>
    </inertial>
    <visual>
      <origin rpy="0 0 0" xyz="0 0 0"/>
      <geometry>
        <mesh filename="package://professor_robot/meshes/mounting_plate_3w.STL"/>
      </geometry>
      <material name="white">
        <color rgba="1 1 1 1"/>
      </material>
    </visual>
    <collision>
      <origin rpy="0 0 0" xyz="0.46 0 -0.002"/>
      <geometry>
        <box size="0.92 0.72 0.004"/>
      </geometry>
    </collision>
  </link>
  <joint name="mounting_plate_joint" type="fixed">
    <origin rpy="0 0 0" xyz=" -0.02 0 0.05"/>
    <parent link="beam_link"/>
    <child link="mounting_plate"/>
    <axis xyz="0 0 0"/>
  </joint>
  <link name="swing_axle_top">
    <inertial>
      <origin rpy="0 0 0" xyz="0 0 0"/>
      <mass value="1.619"/>
      <inertia ixx="0.0013" ixy="0" ixz="0" iyy="0.00079" iyz="0" izz="0.0006"/>
    </inertial>
    <visual>
      <origin rpy="0 0 0" xyz="0 0 0"/>
      <geometry>
        <mesh filename="package://professor_robot/meshes/swing_axle_top.STL"/>
      </geometry>
      <material name="white">
        <color rgba="1 1 1 1"/>
      </material>
    </visual>
    <collision>
      <origin rpy="0 0 0" xyz="0.21 0.27 0.15"/>
      <geometry>
        <box size="0.150 0.15 0.08"/>
      </geometry>
    </collision>
  </link>
  <joint name="swing_axle_top_joint" type="fixed">
    <origin rpy="0 0 1.5707963267948966" xyz="1.02 -0.215 -0.2"/>
    <parent link="beam_link"/>
    <child link="swing_axle_top"/>
    <axis xyz="0 0 0"/>
  </joint>
  <link name="swing_axle_bot">
    <inertial>
      <origin rpy="0 0 0" xyz="-1.254E-10 -0.025528 -1.137E-10"/>
      <mass value="3.1467"/>
      <inertia ixx="0.00294" ixy="0" ixz="0" iyy="0.01932" iyz="0" izz="0.01712"/>
    </inertial>
    <visual>
      <origin rpy="0 0 0" xyz="0 0 0"/>
      <geometry>
        <mesh filename="package://professor_robot/meshes/swing_axle_bot.STL"/>
      </geometry>
      <material name="white">
        <color rgba="1 1 1 1"/>
      </material>
    </visual>
    <collision>
      <origin rpy="0 0 0" xyz="0 0 0"/>
      <geometry>
        <box size="0.60 0.05 0.16"/>
      </geometry>
    </collision>
  </link>
  <joint name="swing_axle_joint" type="continuous">
    <origin rpy="1.5708 0 0" xyz="0.21389 0.29648 0.16159"/>
    <parent link="swing_axle_top"/>
    <child link="swing_axle_bot"/>
    <axis xyz="0 0 1"/>
  </joint>
  <link name="caster_left">
    <inertial>
      <origin rpy="0 0 0" xyz="-0.023 0 -0.062"/>
      <mass value="2.9"/>
      <inertia ixx="0.016" ixy="0" ixz="0.005" iyy="0.016" iyz="0" izz="0.01"/>
    </inertial>
    <visual>
      <origin rpy="0 0 0" xyz="0 0 0"/>
      <geometry>
        <mesh filename="package://professor_robot/meshes/caster_bot.STL"/>
      </geometry>
      <material name="white">
        <color rgba="1 1 1 1"/>
      </material>
    </visual>
    <collision>
      <origin rpy="0 0 0" xyz="0 0 -0.05"/>
      <geometry>
        <cylinder length="0.09" radius="0.07"/>
      </geometry>
    </collision>
  </link>
  <link name="caster_wheel_left">
    <inertial>
      <origin rpy="0 0 0" xyz="0 0 0"/>
      <mass value="5"/>
      <inertia ixx="0.017" ixy="0" ixz="0" iyy="0.030" iyz="0" izz="0.017"/>
    </inertial>
    <visual>
      <origin rpy="0 0 0" xyz="0 0 0"/>
      <geometry>
        <mesh filename="package://professor_robot/meshes/caster_wheel.STL"/>
      </geometry>
      <material name="">
        <color rgba="0.25 0.25 0.25 1"/>
      </material>
    </visual>
    <collision>
      <origin rpy="-1.57 0 0" xyz="0 0.01 0 "/>
      <geometry>
        <cylinder length="0.085" radius="0.125"/>
      </geometry>
    </collision>
  </link>
  <gazebo reference="caster_wheel_left">
    <!-- <mu1>0.2</mu1>
    <mu2>0.2</mu2>-->
    <material>Gazebo/Grey</material>
  </gazebo>
  <joint name="caster_wheel_left_joint" type="continuous">
    <origin rpy="0 0 0.003" xyz="-0.08 -0.014 -0.17"/>
    <parent link="caster_left"/>
    <child link="caster_wheel_left"/>
    <axis xyz="0 1 0"/>
  </joint>
  <link name="caster_right">
    <inertial>
      <origin rpy="0 0 0" xyz="-0.023 0 -0.062"/>
      <mass value="2.9"/>
      <inertia ixx="0.016" ixy="0" ixz="0.005" iyy="0.016" iyz="0" izz="0.01"/>
    </inertial>
    <visual>
      <origin rpy="0 0 0" xyz="0 0 0"/>
      <geometry>
        <mesh filename="package://professor_robot/meshes/caster_bot.STL"/>
      </geometry>
      <material name="white">
        <color rgba="1 1 1 1"/>
      </material>
    </visual>
    <collision>
      <origin rpy="0 0 0" xyz="0 0 -0.05"/>
      <geometry>
        <cylinder length="0.09" radius="0.07"/>
      </geometry>
    </collision>
  </link>
  <link name="caster_wheel_right">
    <inertial>
      <origin rpy="0 0 0" xyz="0 0 0"/>
      <mass value="5"/>
      <inertia ixx="0.017" ixy="0" ixz="0" iyy="0.030" iyz="0" izz="0.017"/>
    </inertial>
    <visual>
      <origin rpy="0 0 0" xyz="0 0 0"/>
      <geometry>
        <mesh filename="package://professor_robot/meshes/caster_wheel.STL"/>
      </geometry>
      <material name="">
        <color rgba="0.25 0.25 0.25 1"/>
      </material>
    </visual>
    <collision>
      <origin rpy="-1.57 0 0" xyz="0 0.01 0 "/>
      <geometry>
        <cylinder length="0.085" radius="0.125"/>
      </geometry>
    </collision>
  </link>
  <gazebo reference="caster_wheel_right">
    <!-- <mu1>0.2</mu1>
    <mu2>0.2</mu2>
    <limit effort="0" velocity="0" />-->
    <material>Gazebo/Grey</material>
  </gazebo>
  <joint name="caster_wheel_right_joint" type="continuous">
    <origin rpy="0 0 0.003" xyz="-0.08 -0.014 -0.17"/>
    <parent link="caster_right"/>
    <child link="caster_wheel_right"/>
    <axis xyz="0 1 0"/>
  </joint>
  <joint name="caster_left_joint" type="continuous">
    <origin rpy="-1.5707963267948966 -1.5707963267948966 0" xyz="-0.215 -0.055 0"/>
    <parent link="swing_axle_bot"/>
    <child link="caster_left"/>
    <axis xyz="0 0 1"/>
  </joint>
  <joint name="caster_right_joint" type="continuous">
    <origin rpy="-1.5707963267948966 -1.5707963267948966 0" xyz="0.215 -0.055 0"/>
    <parent link="swing_axle_bot"/>
    <child link="caster_right"/>
    <axis xyz="0 0 1"/>
  </joint>
  <gazebo>
    <plugin filename="libgazebo_ros_control.so" name="gazebo_ros_control">
      <robotNamespace>/</robotNamespace>
    </plugin>
  </gazebo>
  <update_rate>1</update_rate>
</robot>

